<?xml version="1.0"?>


<robot xmlns:xacro="http://www.ros.org/wiki/xacro" name="modubot">

  <xacro:macro name="wheel" params="prefix">
    <link name="${prefix}_wheel">
      <visual>
        <origin xyz="0 0 0" rpy="0 0 0" />
        <geometry>
          <cylinder length="0.2" radius="0.3" />
        </geometry>
        <material name="Blue">
          <color rgba="0.0 0.0 1.0 1.0" />
        </material>
      </visual>
    </link>
  </xacro:macro>

  <xacro:macro name="caster_wheel" params="prefix">
    <link name="${prefix}_caster" />
  
    <xacro:wheel prefix="${prefix}" />
  
    <joint name="${prefix}_wheel_caster" type="continuous">
      <parent link="${prefix}_caster" />
      <child link="${prefix}_wheel" />
    </joint>
  </xacro:macro>

  <xacro:wheel prefix="rear_left" />
  <xacro:wheel prefix="rear_right" />
  <xacro:caster_wheel prefix="front_left" />
  <xacro:caster_wheel prefix="front_right" />
  
  <link name="platform">
    <visual>
      <geometry>
        <box size="2 2 1" /> 
      </geometry>
    </visual>
  </link>

  <joint name="platform_left_caster" type="continuous">
    <parent link="platform" />
    <child link="front_left_caster" />
  </joint>

  <joint name="platform_right_caster" type="continuous">
    <parent link="platform" />
    <child link="front_right_caster" />
  </joint>

  <joint name="platform_left_wheel" type="continuous">
    <parent link="platform" />
    <child link="rear_left_wheel" />
  </joint>

  <joint name="platform_right_wheel" type="continuous">
    <parent link="platform" />
    <child link="rear_right_wheel" />
  </joint>

</robot>
